Workbook

Sheet README
B1: Data Extraction Form — Tetracyclines & Clostridioides difficile Infection
B3: Systematic review & Bayesian random-effects meta-analysis (University of Padua thesis). Companion to the registered PROSPERO protocol.
B5: PURPOSE
B6: Structured, dual-reviewer extraction of the tetracycline-class vs other-antibiotic association with INCIDENT CDI, plus combination therapy and covariates, in a form whose output feeds the Bayesian model directly (per-study log-OR and its standard error).
B8: WORKFLOW (per PROSPERO §16–17)
B9: 1. Register PROSPERO before any extraction. Screening/scoping only until then.
B10: 2. TWO reviewers extract each study independently into their own copy of this workbook.
B11: 3. One row per STUDY in 'Studies'; one row per reported EFFECT ESTIMATE in 'Estimates' (a study can have many).
B12: 4. Prefer the ADJUSTED estimate; if only crude data exist, enter the 2x2 counts and the sheet computes the crude log-OR.
B13: 5. Flag exactly ONE estimate per study as Used_in_primary = Yes; 'Analysis_dataset' then auto-pulls its log-OR + SE.
B14: 6. Reconcile the two extractions; record disagreements and Cohen's kappa; a third reviewer breaks ties.
B15: 7. Complete risk of bias (NOS for observational, RoB2 for RCTs) and the covariate/adjustment matrix.
B17: LEGEND
C18: Enter data here
C19: Auto-computed (do not type over)
C20: Example row — delete before use
C21: Pre-seeded, UNVERIFIED — verify vs source
B23: SHEETS
B24: • Codebook — every variable, its type, allowed values, definition, and PROSPERO reference.
B25: • Studies — one row per study (bibliographic, design, setting, population, CDI definition).
B26: • Estimates — one row per effect estimate; holds tetracycline-vs-comparator AND each antibiotic class's own CDI estimate. Auto-computes yi = log-OR and sei.
B27: • Combination_therapy — whether tetracycline was combined with other agents and any combination-specific CDI estimate.
B28: • Covariate_matrix — what each study adjusted/matched/stratified for (confounding + meta-regression).
B29: • RoB_NOS — Newcastle-Ottawa Scale (cohort & case-control).
B30: • RoB2_RCT — Cochrane RoB 2 (randomized trials).
B31: • Analysis_dataset — auto-derived per-study yi & sei ready for brms / bayesmeta / PyMC.
B32: • Lookups — drop-down source lists (do not edit).
B34: BAYESIAN MODEL THIS FEEDS (PROSPERO §19)
B35: yi ~ Normal(theta_i, sei^2); theta_i ~ Normal(mu, tau^2); mu ~ Normal(0,1^2); tau ~ Half-Normal(0,0.5).
... B39: Reviewer: __________ Independent-copy ID: ______ Date started: __________

Sheet Codebook
A1: Sheet | B1: Variable | C1: Label / prompt | D1: Type | E1: Allowed values / units | F1: Definition & extraction instruction | G1: PROSPERO ref
A2: Studies | B2: Study_ID | C2: Study identifier | D2: text | E2: S01, S02, … | F2: Unique per study; primary key linking all sheets. | G2: §16
A3: Studies | B3: First_author | C3: First author | D3: text | E3: surname
A4: Studies | B4: Year | C4: Publication year | D4: number | E4: yyyy
A5: Studies | B5: Design | C5: Study design | D5: list | E5: see Lookups:design | F5: Cohort / case-control / RCT etc. | G5: §13-S,17
A6: Studies | B6: Setting | C6: Care setting | D6: list | E6: see Lookups:setting | G6: §17
A7: Studies | B7: Care_context | C7: CDI acquisition context | D7: list | E7: see Lookups:care_context | F7: HA vs CA CDI (subgroup). | G7: §19
A8: Studies | B8: Age_group | C8: Population age | D8: list | E8: see Lookups:age_group
A9: Studies | B9: N_total | C9: Total sample | D9: number | E9: persons | F9: Denominator / cohort or case+control total. | G9: §17
A10: Studies | B10: N_CDI_cases | C10: CDI events | D10: number | E10: persons | F10: Incident CDI cases. | G10: §17
A11: Studies | B11: CDI_case_definition | C11: CDI definition | D11: text | E11: free text | F11: Author definition (test + clinical). | G11: §13-O
A12: Studies | B12: CDI_test_method | C12: Diagnostic method | D12: list | E12: see Lookups:test_method | G12: §13-O
A13: Studies | B13: Tetracycline_agents | C13: Tetracycline agent(s) | D13: text | E13: free text | F13: Agents examined & route. | G13: §17
A14: Studies | B14: Comparator_definition | C14: Comparator | D14: text | E14: free text | F14: What tetracycline is compared with. | G14: §13-C
A15: Studies | B15: Analysis_method | C15: Analytic method | D15: text | E15: free text | F15: e.g., multivariable logistic, Cox, conditional logistic. | G15: §17
A16: Studies | B16: Include_primary | C16: In primary analysis? | D16: list | E16: see Lookups:yesno | F16: No = record only (e.g., comparator is 'no antibiotic'). | G16: §13-C
A17: Studies | B17: Provenance | C17: Source of record | D17: list | E17: see Lookups:provenance | F17: Tariq carry-forward vs new include. | G17: §13
A18: Estimates | B18: Estimate_ID | C18: Estimate identifier | D18: text | E18: E01, E02, … | F18: One row per reported estimate.
A19: Estimates | B19: Study_ID | C19: Parent study | D19: text | E19: S01… | F19: Foreign key to Studies.
A20: Estimates | B20: Exposure_item | C20: Exposure | D20: list | E20: see Lookups:exposure_item | F20: The drug/class this estimate is FOR (enables per-class matrix). | G20: §13-E
A21: Estimates | B21: Exposure_grouping | C21: Exposure type | D21: list | E21: see Lookups:exposure_grouping
A22: Estimates | B22: Comparator_type | C22: Comparator | D22: list | E22: see Lookups:comparator_type | F22: Primary = 'Other antibiotics (pooled)'. | G22: §13-C
A23: Estimates | B23: Subgroup | C23: Subgroup/stratum | D23: list | E23: see Lookups:subgroup | F23: Doxycycline-only, HA/CA, etc. | G23: §19
A24: Estimates | B24: Estimate_type | C24: Metric | D24: list | E24: see Lookups:estimate_type | F24: OR/RR/HR/IRR as reported. | G24: §17
A25: Estimates | B25: Adjusted | C25: Adjustment | D25: list | E25: see Lookups:adjusted | F25: Adjusted preferred. | G25: §17
A26: Estimates | B26: Point_estimate | C26: Point estimate | D26: number | E26: >0 | F26: As reported. | G26: §17
A27: Estimates | B27: CI_lower / CI_upper | C27: 95% CI | D27: number | E27: >0 | F27: Confidence limits. | G27: §17
A28: Estimates | B28: CI_level | C28: CI level | D28: number | E28: 90/95/99 | F28: Default 95.
A29: Estimates | B29: a,b,c,d | C29: 2x2 counts | D29: number | E29: persons | F29: a=exposed+CDI, b=exposed+noCDI, c=unexposed+CDI, d=unexposed+noCDI. Enter when only crude data given. | G29: §17
A30: Estimates | B30: yi_logOR (auto) | C30: log effect | D30: formula | E30: — | F30: Auto: LN(point) or LN((a·d)/(b·c)). Feeds the model. | G30: §19
A31: Estimates | B31: sei (auto) | C31: SE of log effect | D31: formula | E31: — | F31: Auto: (LN(CIu)−LN(CIl))/(2z) or sqrt(1/a+1/b+1/c+1/d). | G31: §19
A32: Estimates | B32: Used_in_primary | C32: Primary flag | D32: list | E32: see Lookups:used_primary | F32: Exactly one Yes per study. | G32: §19
A33: Estimates | B33: Scale_note | C33: Metric caveat | D33: text | E33: free text | F33: Flag HR/RR-as-OR, per-day HR, etc. | G33: §17
A34: Estimates | B34: Verified | C34: Verification | D34: list | E34: see Lookups:verified | F34: Set to Verified after human check vs source. | G34: §16
A35: Combination_therapy | B35: Combination_present | C35: Combo present? | D35: list | E35: see Lookups:yesno | F35: Tetracycline co-administered with another agent. | G35: user req.
A36: Combination_therapy | B36: Co_administered_agents | C36: Partner agent(s) | D36: text | E36: free text | F36: e.g., doxycycline + ciprofloxacin.
A37: Combination_therapy | B37: Combo_context | C37: Context | D37: list | E37: see Lookups:combo_context | F37: Prophylaxis / treatment / co-exposure / trial arm.
A38: Combination_therapy | B38: Combo_* estimate | C38: Combo-specific CDI estimate | D38: number | E38: — | F38: If a combination-specific CDI estimate is reported.
A39: Covariate_matrix | B39: <covariate> | C39: Adjustment status | D39: list | E39: see Lookups:adj_status | F39: A/M/S/N/NR for each covariate — documents confounding control. | G39: §17,19
A40: RoB_NOS | B40: S/C/O items | C40: Newcastle-Ottawa stars | D40: list | E40: star01 / star012 | F40: Selection(4★), Comparability(2★), Outcome/Exposure(3★). | G40: §18
...

Sheet Studies
A1: Study_ID | B1: First_author | C1: Year | D1: Title | E1: Journal | F1: DOI | G1: PMID | H1: Country | I1: Setting | J1: Care_context | K1: Design | L1: Recruit_start | M1: Recruit_end | N1: N_total | O1: N_CDI_cases | P1: Age_group | Q1: Population_description | R1: CDI_case_definition | S1: CDI_test_method | T1: Tetracycline_agents | U1: Comparator_definition | V1: Analysis_method | W1: Include_primary | X1: Provenance | Y1: Extractor | Z1: Extraction_date | AA1: Notes
A2: EX-01 | B2: Example | C2: 2020 | D2: EXAMPLE — delete this row before use | E2: J Example | F2: 10.xxxx/ex | G2: 00000000 | H2: Country | I2: Hospital/acute care | J2: HA-CDI (healthcare-associated) | K2: Case-control | L2: 2015 | M2: 2018 | N2: 1000 | O2: 120 | P2: Adults (>=18) | Q2: Example population description | R2: Positive NAAT + diarrhea | S2: NAAT/PCR | T2: Doxycycline | U2: Other antibiotics | V2: Multivariable logistic | W2: Yes | X2: other | Y2: AB | Z2: 2026-08-01 | AA2: Example row showing expected format.
A3: S01 | B3: Adams | C3: 2017 | D3: Risk Factors for Community-Associated C. difficile Infection in Children | I3: Community | J3: CA-CDI (community-associated) | K3: Case-control | N3: 3993 | T3: Tetracyclines | U3: Other antibiotics | W3: Yes | X3: other | AA3: Pediatric CA-CDI.
A4: S02 | B4: Bartoletti | C4: 2018 | D4: Differences in rate of CRE colonisation or CDI: tigecycline- vs meropenem-based regimen | I4: Hospital/acute care | J4: HA-CDI (healthcare-associated) | K4: Matched case-control | N4: 336 | T4: Tigecycline | U4: Meropenem-based regimen | W4: Unclear | X4: other | AA4: Outcome is COMPOSITE (CRE colonisation OR CDI); not CDI-specific.
A5: S03 | B5: Baxter | C5: 2008 | D5: Case-Control Study of Antibiotic Use and Subsequent CDAD | I5: Hospital/acute care | J5: HA-CDI (healthcare-associated) | K5: Case-control | N5: 2355 | T5: Doxycycline | U5: Other antibiotics | W5: Yes | X5: other | AA5: Doxycycline protective; metronidazole also 0.67.
A6: S04 | B6: Bejcek | C6: 2024 | D6: Antibiotic use and risk of CDI in patients with IBD | I6: Hospital/acute care | J6: HA-CDI (healthcare-associated) | K6: Retrospective cohort | N6: 24832 | T6: Tetracyclines | U6: Other antibiotics | W6: Unclear | X6: other | AA6: IBD subpopulation; matched; exact OR not auto-extracted (p=0.010).
A7: S05 | B7: Bernatz | C7: 2017 | D7: Antibiotic Overuse is a Major Risk Factor for CDI in Surgical Patients | I7: Hospital/acute care | J7: HA-CDI (healthcare-associated) | K7: ? | T7: (none) | W7: No | X7: other | AA7: No tetracycline-specific estimate detected.
A8: S06 | B8: Boven | C8: 2026 | D8: Commonly prescribed drugs as risk factors for CDI: a Swedish population study | I8: Mixed | J8: Mixed/Both | K8: Case-control | T8: Tetracyclines | U8: Other antibiotics / non-users | W8: Yes | X8: other | AA8: Population-based; crude 2.03, adjusted models reported.
A9: S07 | B9: Brown | C9: 2015 | D9: Hospital ward antibiotic prescribing and the risks of CDI | I9: Hospital/acute care | J9: HA-CDI (healthcare-associated) | K9: Retrospective cohort | N9: 255 | T9: (ward-level) | W9: No | X9: other | AA9: Ward-level prescribing; no individual tetracycline estimate.
A10: S08 | B10: Brown | C10: 2016 | D10: Importation, Antibiotics, and CDI in Veteran Long-Term Care | I10: Hospital/acute care | J10: HA-CDI (healthcare-associated) | K10: Retrospective cohort | T10: (none) | W10: No | X10: other | AA10: No tetracycline mention detected.
A11: S09 | B11: Brown | C11: 2020 | D11: Antibiotic prescribing choices and their comparative CDI risks | I11: Hospital/acute care | J11: Mixed/Both | K11: Retrospective cohort | N11: 181 | T11: Tetracycline | U11: Other antibiotics | W11: Yes | X11: other | AA11: Comparative CDI risk ratios.
A12: S10 | B12: Brown | C12: 2026 | D12: Antibiotic and Nonantibiotic Drugs Associated With CDI Risk (PheWAS) | I12: Hospital/acute care | J12: Mixed/Both | K12: Retrospective cohort | N12: 549 | T12: (none) | W12: No | X12: other | AA12: No tetracycline mention detected.
A13: S11 | B13: Carmichael | C13: 2023 | D13: C. difficile and other adverse events from overprescribed antibiotics (aURI) | E13: J Intern Med | I13: Community | J13: Mixed/Both | K13: Retrospective cohort | T13: Doxycycline | U13: Other antibiotics | W13: Yes | X13: other | AA13: Doxycycline aOR 0.94 (~0.89-0.99) from full-text (protective).
A14: S12 | B14: Cazali | C14: 2018 | D14: 486. Endemic Corridors: a tool for C. difficile (conf abstract) | I14: Hospital/acute care | J14: HA-CDI (healthcare-associated) | K14: Cross-sectional | N14: 2823 | T14: (none) | W14: No | X14: other | AA14: Conference abstract; no extractable tetracycline estimate.
A15: S13 | B15: Chalmers | C15: 2016 | D15: Risk factors for CDI in hospitalized patients with community-acquired pneumonia | I15: Hospital/acute care | J15: Mixed/Both | K15: Retrospective cohort | N15: 1883 | T15: Tetracyclines | U15: Other antibiotics | W15: Unclear | X15: other | AA15: Tetracyclines OR 0.9 (no CI); doxycycline often combined with macrolides.
A16: S14 | B16: Cui | C16: 2023 | D16: Epidemiological surveillance (2021-2022): high diversity of C. difficile | I16: Hospital/acute care | J16: Mixed/Both | K16: Case-control | N16: 3200 | T16: Tetracyclines | U16: Reference category | W16: Yes | X16: other | AA16: Very wide CI; univariable OR 15.2.
A17: S15 | B17: Dai | C17: 2020 | D17: Characteristics of C. difficile isolates and burden of HA-CDI | I17: Hospital/acute care | J17: HA-CDI (healthcare-associated) | K17: Case-control | N17: 211536 | T17: Tigecycline | W17: No | X17: other | AA17: Tigecycline only in MIC/susceptibility context (microbiology).
A18: S16 | B18: Dang | C18: 2021 | D18: Impact of Antecedent Antibiotic Usage on CA-CDI | I18: Community | J18: CA-CDI (community-associated) | K18: Case-control | N18: 408 | T18: Doxycycline | U18: Other antibiotics | W18: Unclear | X18: other | AA18: Doxycycline reported significant; exact estimate not auto-extracted.
A19: S17 | B19: Delaney | C19: 2007 | D19: Antimicrobial drugs and community-acquired CDAD, UK | E19: Emerg Infect Dis | I19: Community | J19: CA-CDI (community-associated) | K19: Case-control | N19: 12330 | T19: Tetracyclines | U19: Other antibiotics | W19: Yes | X19: other | AA19: GPRD case-control.
A20: S18 | B20: Dial | C20: 2008 | D20: Patterns of antibiotic use and risk of hospital admission for CDI | E20: CMAJ | I20: Community | J20: Mixed/Both | K20: Nested case-control | N20: 8360 | T20: Tetracyclines | U20: Unexposed / other | W20: Yes | X20: tariq-2018 (carried forward) | AA20: Tariq anchor.
A21: S19 | B21: Doernberg | C21: 2012 | D21: Does doxycycline protect against development of CDI? | E21: Clin Infect Dis | I21: Hospital/acute care | J21: HA-CDI (healthcare-associated) | K21: Retrospective cohort | N21: 1668 | T21: Doxycycline | U21: Ceftriaxone without doxycycline | W21: Yes | X21: tariq-2018 (carried forward) | AA21: Tariq anchor; incidence 1.67 vs 8.11/10k pt-days.
A22: S20 | B22: Forster | C22: 2017 | D22: Influence of antibiotics and case exposure on HA-CDI | I22: Hospital/acute care | J22: HA-CDI (healthcare-associated) | K22: ? | T22: (none) | W22: No | X22: other | AA22: No tetracycline mention detected.
A23: S21 | B23: Gilboa | C23: 2025 | D23: Antibiotic Use and the Risk of Hospital-Onset CDI | I23: Hospital/acute care | J23: HA-CDI (healthcare-associated) | K23: Retrospective cohort | N23: 1624 | T23: Tetracyclines (grouped) | U23: Other antibiotics | W23: No | X23: other | AA23: Tetracyclines folded into 'other antibiotics'; no separable estimate.
A24: S22 | B24: Greco Kinney | C24: 2023 | D24: Beta-lactams plus doxycycline vs azithromycin for severe CAP | I24: Community | J24: CA-CDI (community-associated) | K24: Retrospective cohort | N24: 880 | T24: Doxycycline (combination) | U24: Azithromycin | W24: Unclear | X24: other | AA24: Treatment comparison; CDI outcome unclear from text; combination therapy.
A25: S23 | B25: Guh | C25: 2015 | D25: Risk Factors for CA-CDI in Adults: A Case-Control Study | I25: Community | J25: CA-CDI (community-associated) | K25: Case-control | N25: 452 | T25: Tetracycline | U25: Other antibiotics | W25: Yes | X25: other | AA25: 2x2 available.
A26: S24 | B26: Guo | C26: 2021 | D26: Trends in incidence and clinical outcomes of CDI, Hong Kong | E26: Emerg Infect Dis | I26: Hospital/acute care | J26: Mixed/Both | K26: Retrospective cohort | N26: 17105 | T26: Tetracyclines | U26: Other antibiotics | W26: Yes | X26: other | AA26: Crude 1.291; adjusted 1.219.
A27: S25 | B27: Hensgens | C27: 2012 | D27: Time interval of increased risk for CDI after antibiotic exposure | I27: Community | J27: CA-CDI (community-associated) | K27: Case-control | N27: 337 | T27: (not detected) | W27: Unclear | X27: other | AA27: No tetracycline line auto-detected; check antibiotic-class table.
A28: S26 | B28: Ito | C28: 2025 | D28: Step-down Therapy with Oral Minocycline for Complicated Pyelonephritis | I28: Hospital/acute care | J28: Mixed/Both | K28: Retrospective cohort | T28: Minocycline | W28: No | X28: other | AA28: Outcome = treatment efficacy/relapse, NOT incident CDI.
A29: S27 | B29: John | C29: 2018 | D29: 517. Impact of Doxycycline in Place of Azithromycin for CAP on CDI (abstract) | I29: Mixed | J29: Mixed/Both | K29: Retrospective cohort | T29: Doxycycline | U29: Azithromycin | W29: Unclear | X29: other | AA29: Conf abstract; doxycycline substitution vs azithromycin; extract CDI from source.
A30: S28 | B30: Katz | C30: 2017 | D30: Incidence of Pediatric CA-CDI Following Common Antibiotics (abstract) | I30: Community | J30: CA-CDI (community-associated) | K30: Retrospective cohort | T30: Doxycycline | U30: Other antibiotics | W30: Unclear | X30: other | AA30: Pediatric; doxycycline CDI count reported; comparator unclear.
A31: S29 | B31: Kavanagh | C31: 2016 | D31: Cumulative/temporal associations between prescribing and CA-CDI | I31: Community | J31: Mixed/Both | K31: ? | T31: (not detected) | W31: No | X31: other | AA31: Consumption/temporal; no individual tetracycline estimate.
A32: S30 | B32: Khanafer | C32: 2017 | D32: Factors associated with CDI: a nested case-control study | I32: Hospital/acute care | J32: HA-CDI (healthcare-associated) | K32: Nested case-control | N32: 3514 | T32: (not detected) | W32: No | X32: other | AA32: No tetracycline mention detected.
A33: S31 | B33: King | C33: 2011 | D33: Incidence of CDI in Patients Receiving Antimicrobial and Acid-Suppressive Therapy | I33: Hospital/acute care | J33: HA-CDI (healthcare-associated) | K33: Retrospective cohort | N33: 101796 | T33: (not detected) | W33: No | X33: other | AA33: No tetracycline mention detected.
A34: S32 | B34: Kuntz | C34: 2011 | D34: Incidence of and risk factors for CA-CDI: a nested case-control study | E34: BMC Infect Dis | I34: Community | J34: CA-CDI (community-associated) | K34: Nested case-control | N34: 304 | T34: Tetracyclines | U34: Other antibiotics | W34: Yes | X34: tariq-2018 (carried forward) | AA34: Tariq anchor; crude 1.43, adjusted 0.94.
A35: S33 | B35: Levy | C35: 2000 | D35: Antibiotics and C. difficile diarrhea in the ambulatory care setting | I35: Community | J35: CA-CDI (community-associated) | K35: Retrospective cohort | T35: Doxycycline; Minocycline; Tetracycline | U35: Other antibiotics | W35: Unclear | X35: other | AA35: Per-antibiotic CDD incidence/counts; no OR vs comparator.
A36: S34 | B36: Liu | C36: 2024 | D36: CDI Risk Following Different Antibiotics: Multi-source insights | I36: Mixed | J36: Mixed/Both | K36: Retrospective cohort | N36: 185930 | T36: Tigecycline | U36: Other antibiotics | W36: Unclear | X36: other | AA36: Tigecycline OR 0.10 (protective, CI incomplete); tetracycline class not separately estimable.
A37: S35 | B37: Manges | C37: 2010 | D37: Comparative metagenomic study and risk of nosocomial CDI | I37: Hospital/acute care | J37: HA-CDI (healthcare-associated) | K37: Nested case-control | N37: 1461 | T37: Tetracyclines | U37: Other antibiotics | W37: No | X37: other | AA37: Zero tetracycline exposure in both groups (0 vs 0); not usable.
A38: S36 | B38: Miller | C38: 2020 | D38: Risk for CDI among hospitalized patients with multiple antibiotics | I38: Hospital/acute care | J38: Mixed/Both | K38: Case-control | T38: (not detected) | W38: No | X38: other | AA38: No tetracycline line detected.
A39: S37 | B39: Miller | C39: 2023 | D39: Comparison of Different Antibiotics and Risk for CA-CDI | I39: Community | J39: CA-CDI (community-associated) | K39: Retrospective cohort | N39: 905 | T39: Doxycycline; Minocycline; Tetracycline | U39: Other antibiotics | W39: Yes | X39: other | AA39: Per-agent aORs (doxy 0.96, mino 0.79, tetracycline 1.21).
A40: S38 | B40: Minson | C40: 2007 | D40: Relationship between Antibiotic Exposure and Subsequent CDAD | I40: Hospital/acute care | J40: HA-CDI (healthcare-associated) | K40: Case-control | T40: (not detected) | W40: No | X40: other | AA40: No tetracycline mention detected.
...

Sheet Estimates
A1: Estimate_ID | B1: Study_ID | C1: Exposure_item | D1: Exposure_grouping | E1: Comparator_type | F1: Comparator_detail | G1: Subgroup | H1: Estimate_type | I1: Adjusted | J1: Point_est | K1: CI_lower | L1: CI_upper | M1: CI_level | N1: P_value | O1: a_exp_CDI | P1: b_exp_noCDI | Q1: c_unexp_CDI | R1: d_unexp_noCDI | S1: z (auto) | T1: logEff_pt (auto) | U1: SE_CI (auto) | V1: logOR_2x2 (auto) | W1: SE_2x2 (auto) | X1: yi_logOR (auto) | Y1: sei (auto) | Z1: OR_disp (auto) | AA1: Used_in_primary | AB1: primary_key (auto) | AC1: Scale_note | AD1: Source_table/page | AE1: Verified | AF1: Notes
A2: EX-01 | B2: EX-01 | C2: Doxycycline | D2: Individual tetracycline agent | E2: Other antibiotics (pooled) | F2: vs all non-tetracycline abx | G2: Overall / primary | H2: aOR | I2: Adjusted (multivariable) | J2: 0.55 | K2: 0.4 | L2: 0.75 | M2: 95 | N2: 0.001 | S2: =IF(M2="",1.96,IF(M2=90,1.645,IF(M2=99,2.576,1.96))) | T2: =IFERROR(LN(J2),"") | U2: =IFERROR((LN(L2)-LN(K2))/(2*S2),"") | V2: =IFERROR(LN((O2*R2)/(P2*Q2)),"") | W2: =IFERROR(SQRT(1/O2+1/P2+1/Q2+1/R2),"") | X2: =IFERROR(IF(T2<>"",T2,V2),"") | Y2: =IFERROR(IF(U2<>"",U2,W2),"") | Z2: =IFERROR(EXP(X2),"") | AB2: =IF(AA2="Yes",B2,"") | AC2: Table 2, p.4 | AD2: Verified (single) | AE2: EXAMPLE row — delete before use
A3: E01 | B3: S01 | C3: Tetracyclines (class, pooled) | D3: Tetracycline-class (pooled) | E3: Other antibiotics (pooled) | G3: Overall / primary | H3: aOR | I3: Adjusted (multivariable) | J3: 1.26 | K3: 0.46 | L3: 3.44 | M3: 95 | S3: =IF(M3="",1.96,IF(M3=90,1.645,IF(M3=99,2.576,1.96))) | T3: =IFERROR(LN(J3),"") | U3: =IFERROR((LN(L3)-LN(K3))/(2*S3),"") | V3: =IFERROR(LN((O3*R3)/(P3*Q3)),"") | W3: =IFERROR(SQRT(1/O3+1/P3+1/Q3+1/R3),"") | X3: =IFERROR(IF(T3<>"",T3,V3),"") | Y3: =IFERROR(IF(U3<>"",U3,W3),"") | Z3: =IFERROR(EXP(X3),"") | AA3: Yes | AB3: =IF(AA3="Yes",B3,"") | AC3: Crude OR 1.72 (0.94-3.13) | AD3: source table (see PDF) | AE3: UNVERIFIED - needs extraction | AF3: Pediatric CA-CDI.
A4: E02 | B4: S02 | C4: Tigecycline | D4: Individual tetracycline agent | E4: Specific class (see detail) | F4: tigecycline- vs meropenem-based regimen | G4: Other | H4: HR | I4: Unclear | M4: 95 | S4: =IF(M4="",1.96,IF(M4=90,1.645,IF(M4=99,2.576,1.96))) | T4: =IFERROR(LN(J4),"") | U4: =IFERROR((LN(L4)-LN(K4))/(2*S4),"") | V4: =IFERROR(LN((O4*R4)/(P4*Q4)),"") | W4: =IFERROR(SQRT(1/O4+1/P4+1/Q4+1/R4),"") | X4: =IFERROR(IF(T4<>"",T4,V4),"") | Y4: =IFERROR(IF(U4<>"",U4,W4),"") | Z4: =IFERROR(EXP(X4),"") | AA4: No | AB4: =IF(AA4="Yes",B4,"") | AC4: Composite outcome (CRE colonisation OR CDI) - not CDI-specific | AD4: source table (see PDF) | AE4: UNVERIFIED - needs extraction | AF4: Verify whether a CDI-only estimate exists.
A5: E03 | B5: S03 | C5: Doxycycline | D5: Individual tetracycline agent | E5: Other antibiotics (pooled) | G5: Overall / primary | H5: aOR | I5: Adjusted (multivariable) | J5: 0.41 | K5: 0.26 | L5: 0.62 | M5: 95 | S5: =IF(M5="",1.96,IF(M5=90,1.645,IF(M5=99,2.576,1.96))) | T5: =IFERROR(LN(J5),"") | U5: =IFERROR((LN(L5)-LN(K5))/(2*S5),"") | V5: =IFERROR(LN((O5*R5)/(P5*Q5)),"") | W5: =IFERROR(SQRT(1/O5+1/P5+1/Q5+1/R5),"") | X5: =IFERROR(IF(T5<>"",T5,V5),"") | Y5: =IFERROR(IF(U5<>"",U5,W5),"") | Z5: =IFERROR(EXP(X5),"") | AA5: Yes | AB5: =IF(AA5="Yes",B5,"") | AC5: Crude 0.55 | AD5: source table (see PDF) | AE5: UNVERIFIED - needs extraction | AF5: Protective; metronidazole also 0.67.
A6: E04 | B6: S04 | C6: Tetracyclines (class, pooled) | D6: Tetracycline-class (pooled) | E6: Other antibiotics (pooled) | F6: IBD patients | G6: Overall / primary | H6: OR | I6: Unclear | M6: 95 | S6: =IF(M6="",1.96,IF(M6=90,1.645,IF(M6=99,2.576,1.96))) | T6: =IFERROR(LN(J6),"") | U6: =IFERROR((LN(L6)-LN(K6))/(2*S6),"") | V6: =IFERROR(LN((O6*R6)/(P6*Q6)),"") | W6: =IFERROR(SQRT(1/O6+1/P6+1/Q6+1/R6),"") | X6: =IFERROR(IF(T6<>"",T6,V6),"") | Y6: =IFERROR(IF(U6<>"",U6,W6),"") | Z6: =IFERROR(EXP(X6),"") | AA6: Maybe | AB6: =IF(AA6="Yes",B6,"") | AC6: IBD subgroup; matched; exact OR not extracted (p=0.010) | AD6: source table (see PDF) | AE6: UNVERIFIED - needs extraction | AF6: Extract adjusted OR from source.
A7: E05 | B7: S06 | C7: Tetracyclines (class, pooled) | D7: Tetracycline-class (pooled) | E7: Other antibiotics (pooled) | G7: Adjusted analysis | H7: aOR | I7: Adjusted (multivariable) | J7: 0.93 | K7: 0.79 | L7: 1.08 | M7: 95 | S7: =IF(M7="",1.96,IF(M7=90,1.645,IF(M7=99,2.576,1.96))) | T7: =IFERROR(LN(J7),"") | U7: =IFERROR((LN(L7)-LN(K7))/(2*S7),"") | V7: =IFERROR(LN((O7*R7)/(P7*Q7)),"") | W7: =IFERROR(SQRT(1/O7+1/P7+1/Q7+1/R7),"") | X7: =IFERROR(IF(T7<>"",T7,V7),"") | Y7: =IFERROR(IF(U7<>"",U7,W7),"") | Z7: =IFERROR(EXP(X7),"") | AA7: Yes | AB7: =IF(AA7="Yes",B7,"") | AC7: Crude 2.03 (1.82-2.27) | AD7: source table (see PDF) | AE7: UNVERIFIED - needs extraction | AF7: Swedish population-based.
A8: E06 | B8: S09 | C8: Tetracycline | D8: Individual tetracycline agent | E8: Other antibiotics (pooled) | G8: Adjusted analysis | H8: aOR | I8: Adjusted (multivariable) | J8: 0.94 | K8: 0.65 | L8: 1.11 | M8: 95 | S8: =IF(M8="",1.96,IF(M8=90,1.645,IF(M8=99,2.576,1.96))) | T8: =IFERROR(LN(J8),"") | U8: =IFERROR((LN(L8)-LN(K8))/(2*S8),"") | V8: =IFERROR(LN((O8*R8)/(P8*Q8)),"") | W8: =IFERROR(SQRT(1/O8+1/P8+1/Q8+1/R8),"") | X8: =IFERROR(IF(T8<>"",T8,V8),"") | Y8: =IFERROR(IF(U8<>"",U8,W8),"") | Z8: =IFERROR(EXP(X8),"") | AA8: Yes | AB8: =IF(AA8="Yes",B8,"") | AC8: Comparative CDI risk; also 1.06 (0.65-1.23) | AD8: source table (see PDF) | AE8: UNVERIFIED - needs extraction | AF8: Confirm adjusted vs crude column.
A9: E07 | B9: S11 | C9: Doxycycline | D9: Individual tetracycline agent | E9: Other antibiotics (pooled) | G9: Overall / primary | H9: aOR | I9: Adjusted (multivariable) | J9: 0.94 | K9: 0.89 | L9: 0.99 | M9: 95 | S9: =IF(M9="",1.96,IF(M9=90,1.645,IF(M9=99,2.576,1.96))) | T9: =IFERROR(LN(J9),"") | U9: =IFERROR((LN(L9)-LN(K9))/(2*S9),"") | V9: =IFERROR(LN((O9*R9)/(P9*Q9)),"") | W9: =IFERROR(SQRT(1/O9+1/P9+1/Q9+1/R9),"") | X9: =IFERROR(IF(T9<>"",T9,V9),"") | Y9: =IFERROR(IF(U9<>"",U9,W9),"") | Z9: =IFERROR(EXP(X9),"") | AA9: Yes | AB9: =IF(AA9="Yes",B9,"") | AC9: Value from full text (protective) | AD9: source table (see PDF) | AE9: UNVERIFIED - needs extraction | AF9: Very large cohort (~51M encounters).
A10: E08 | B10: S13 | C10: Tetracyclines (class, pooled) | D10: Tetracycline-class (pooled) | E10: Other antibiotics (pooled) | G10: Overall / primary | H10: OR | I10: Crude / unadjusted | J10: 0.9 | M10: 95 | S10: =IF(M10="",1.96,IF(M10=90,1.645,IF(M10=99,2.576,1.96))) | T10: =IFERROR(LN(J10),"") | U10: =IFERROR((LN(L10)-LN(K10))/(2*S10),"") | V10: =IFERROR(LN((O10*R10)/(P10*Q10)),"") | W10: =IFERROR(SQRT(1/O10+1/P10+1/Q10+1/R10),"") | X10: =IFERROR(IF(T10<>"",T10,V10),"") | Y10: =IFERROR(IF(U10<>"",U10,W10),"") | Z10: =IFERROR(EXP(X10),"") | AA10: Maybe | AB10: =IF(AA10="Yes",B10,"") | AC10: No CI reported; doxycycline often combined with macrolides | AD10: source table (see PDF) | AE10: UNVERIFIED - needs extraction | AF10: Extract CI if available.
A11: E09 | B11: S14 | C11: Tetracyclines (class, pooled) | D11: Tetracycline-class (pooled) | E11: Reference category (multivariable) | G11: Overall / primary | H11: aOR | I11: Adjusted (multivariable) | J11: 22.459 | K11: 2.447 | L11: 206.121 | M11: 95 | S11: =IF(M11="",1.96,IF(M11=90,1.645,IF(M11=99,2.576,1.96))) | T11: =IFERROR(LN(J11),"") | U11: =IFERROR((LN(L11)-LN(K11))/(2*S11),"") | V11: =IFERROR(LN((O11*R11)/(P11*Q11)),"") | W11: =IFERROR(SQRT(1/O11+1/P11+1/Q11+1/R11),"") | X11: =IFERROR(IF(T11<>"",T11,V11),"") | Y11: =IFERROR(IF(U11<>"",U11,W11),"") | Z11: =IFERROR(EXP(X11),"") | AA11: Yes | AB11: =IF(AA11="Yes",B11,"") | AC11: Univariable 15.214 | AD11: source table (see PDF) | AE11: UNVERIFIED - needs extraction | AF11: Very wide CI - verify.
A12: E10 | B12: S16 | C12: Doxycycline | D12: Individual tetracycline agent | E12: Other antibiotics (pooled) | G12: Overall / primary | H12: OR | I12: Unclear | M12: 95 | S12: =IF(M12="",1.96,IF(M12=90,1.645,IF(M12=99,2.576,1.96))) | T12: =IFERROR(LN(J12),"") | U12: =IFERROR((LN(L12)-LN(K12))/(2*S12),"") | V12: =IFERROR(LN((O12*R12)/(P12*Q12)),"") | W12: =IFERROR(SQRT(1/O12+1/P12+1/Q12+1/R12),"") | X12: =IFERROR(IF(T12<>"",T12,V12),"") | Y12: =IFERROR(IF(U12<>"",U12,W12),"") | Z12: =IFERROR(EXP(X12),"") | AA12: Maybe | AB12: =IF(AA12="Yes",B12,"") | AC12: Reported statistically significant; value not auto-extracted | AD12: source table (see PDF) | AE12: UNVERIFIED - needs extraction | AF12: Extract estimate from source.
A13: E11 | B13: S17 | C13: Tetracyclines (class, pooled) | D13: Tetracycline-class (pooled) | E13: Other antibiotics (pooled) | G13: Overall / primary | H13: aOR | I13: Adjusted (multivariable) | J13: 0.9 | K13: 0.5 | L13: 1.5 | M13: 95 | S13: =IF(M13="",1.96,IF(M13=90,1.645,IF(M13=99,2.576,1.96))) | T13: =IFERROR(LN(J13),"") | U13: =IFERROR((LN(L13)-LN(K13))/(2*S13),"") | V13: =IFERROR(LN((O13*R13)/(P13*Q13)),"") | W13: =IFERROR(SQRT(1/O13+1/P13+1/Q13+1/R13),"") | X13: =IFERROR(IF(T13<>"",T13,V13),"") | Y13: =IFERROR(IF(U13<>"",U13,W13),"") | Z13: =IFERROR(EXP(X13),"") | AA13: Yes | AB13: =IF(AA13="Yes",B13,"") | AD13: source table (see PDF) | AE13: UNVERIFIED - needs extraction | AF13: GPRD case-control.
A14: E12 | B14: S18 | C14: Tetracyclines (class, pooled) | D14: Tetracycline-class (pooled) | E14: No antibiotic / unexposed | G14: Overall / primary | H14: RR | I14: Adjusted (multivariable) | J14: 1.1 | K14: 0.1 | L14: 8.6 | M14: 95 | S14: =IF(M14="",1.96,IF(M14=90,1.645,IF(M14=99,2.576,1.96))) | T14: =IFERROR(LN(J14),"") | U14: =IFERROR((LN(L14)-LN(K14))/(2*S14),"") | V14: =IFERROR(LN((O14*R14)/(P14*Q14)),"") | W14: =IFERROR(SQRT(1/O14+1/P14+1/Q14+1/R14),"") | X14: =IFERROR(IF(T14<>"",T14,V14),"") | Y14: =IFERROR(IF(U14<>"",U14,W14),"") | Z14: =IFERROR(EXP(X14),"") | AA14: Yes | AB14: =IF(AA14="Yes",B14,"") | AD14: source table (see PDF) | AE14: UNVERIFIED - needs extraction | AF14: Tariq anchor (rate ratio).
A15: E13 | B15: S19 | C15: Doxycycline | D15: Individual tetracycline agent | E15: Specific class (see detail) | F15: ceftriaxone recipients +/- doxycycline | G15: Overall / primary | H15: aHR | I15: Adjusted (multivariable) | J15: 0.73 | K15: 0.56 | L15: 0.96 | M15: 95 | S15: =IF(M15="",1.96,IF(M15=90,1.645,IF(M15=99,2.576,1.96))) | T15: =IFERROR(LN(J15),"") | U15: =IFERROR((LN(L15)-LN(K15))/(2*S15),"") | V15: =IFERROR(LN((O15*R15)/(P15*Q15)),"") | W15: =IFERROR(SQRT(1/O15+1/P15+1/Q15+1/R15),"") | X15: =IFERROR(IF(T15<>"",T15,V15),"") | Y15: =IFERROR(IF(U15<>"",U15,W15),"") | Z15: =IFERROR(EXP(X15),"") | AA15: Yes | AB15: =IF(AA15="Yes",B15,"") | AC15: Incidence 1.67 vs 8.11 /10,000 pt-days; crude 0.67 | AD15: source table (see PDF) | AE15: UNVERIFIED - needs extraction | AF15: Tariq anchor.
A16: E14 | B16: S23 | C16: Tetracycline | D16: Individual tetracycline agent | E16: Other antibiotics (pooled) | G16: Overall / primary | H16: OR | I16: Crude / unadjusted | J16: 1 | K16: 0.23 | L16: 4.35 | M16: 95 | O16: 5 | P16: 5 | Q16: 220 | R16: 218 | S16: =IF(M16="",1.96,IF(M16=90,1.645,IF(M16=99,2.576,1.96))) | T16: =IFERROR(LN(J16),"") | U16: =IFERROR((LN(L16)-LN(K16))/(2*S16),"") | V16: =IFERROR(LN((O16*R16)/(P16*Q16)),"") | W16: =IFERROR(SQRT(1/O16+1/P16+1/Q16+1/R16),"") | X16: =IFERROR(IF(T16<>"",T16,V16),"") | Y16: =IFERROR(IF(U16<>"",U16,W16),"") | Z16: =IFERROR(EXP(X16),"") | AA16: Yes | AB16: =IF(AA16="Yes",B16,"") | AC16: 2x2 from counts 5/225 vs 5/223 | AD16: source table (see PDF) | AE16: UNVERIFIED - needs extraction | AF16: CA-CDI.
A17: E15 | B17: S24 | C17: Tetracyclines (class, pooled) | D17: Tetracycline-class (pooled) | E17: Other antibiotics (pooled) | G17: Adjusted analysis | H17: aOR | I17: Adjusted (multivariable) | J17: 1.219 | K17: 0.955 | L17: 1.548 | M17: 95 | S17: =IF(M17="",1.96,IF(M17=90,1.645,IF(M17=99,2.576,1.96))) | T17: =IFERROR(LN(J17),"") | U17: =IFERROR((LN(L17)-LN(K17))/(2*S17),"") | V17: =IFERROR(LN((O17*R17)/(P17*Q17)),"") | W17: =IFERROR(SQRT(1/O17+1/P17+1/Q17+1/R17),"") | X17: =IFERROR(IF(T17<>"",T17,V17),"") | Y17: =IFERROR(IF(U17<>"",U17,W17),"") | Z17: =IFERROR(EXP(X17),"") | AA17: Yes | AB17: =IF(AA17="Yes",B17,"") | AC17: Crude 1.291 (1.081-1.534) | AD17: source table (see PDF) | AE17: UNVERIFIED - needs extraction | AF17: Hong Kong.
A18: E16 | B18: S25 | C18: Tetracyclines (class, pooled) | D18: Tetracycline-class (pooled) | E18: Other antibiotics (pooled) | G18: Overall / primary | H18: OR | I18: Unclear | M18: 95 | S18: =IF(M18="",1.96,IF(M18=90,1.645,IF(M18=99,2.576,1.96))) | T18: =IFERROR(LN(J18),"") | U18: =IFERROR((LN(L18)-LN(K18))/(2*S18),"") | V18: =IFERROR(LN((O18*R18)/(P18*Q18)),"") | W18: =IFERROR(SQRT(1/O18+1/P18+1/Q18+1/R18),"") | X18: =IFERROR(IF(T18<>"",T18,V18),"") | Y18: =IFERROR(IF(U18<>"",U18,W18),"") | Z18: =IFERROR(EXP(X18),"") | AA18: Maybe | AB18: =IF(AA18="Yes",B18,"") | AC18: Tetracycline line not auto-detected | AD18: source table (see PDF) | AE18: UNVERIFIED - needs extraction | AF18: Check antibiotic-class risk table.
A19: E17 | B19: S27 | C19: Doxycycline | D19: Individual tetracycline agent | E19: Specific class (see detail) | F19: vs azithromycin (CAP) | G19: Overall / primary | H19: OR | I19: Unclear | M19: 95 | S19: =IF(M19="",1.96,IF(M19=90,1.645,IF(M19=99,2.576,1.96))) | T19: =IFERROR(LN(J19),"") | U19: =IFERROR((LN(L19)-LN(K19))/(2*S19),"") | V19: =IFERROR(LN((O19*R19)/(P19*Q19)),"") | W19: =IFERROR(SQRT(1/O19+1/P19+1/Q19+1/R19),"") | X19: =IFERROR(IF(T19<>"",T19,V19),"") | Y19: =IFERROR(IF(U19<>"",U19,W19),"") | Z19: =IFERROR(EXP(X19),"") | AA19: Maybe | AB19: =IF(AA19="Yes",B19,"") | AC19: Conf abstract; doxycycline substitution | AD19: source table (see PDF) | AE19: UNVERIFIED - needs extraction | AF19: Extract CDI comparison from source.
A20: E18 | B20: S28 | C20: Doxycycline | D20: Individual tetracycline agent | E20: Other antibiotics (pooled) | F20: pediatric | G20: Overall / primary | H20: OR | I20: Unclear | M20: 95 | S20: =IF(M20="",1.96,IF(M20=90,1.645,IF(M20=99,2.576,1.96))) | T20: =IFERROR(LN(J20),"") | U20: =IFERROR((LN(L20)-LN(K20))/(2*S20),"") | V20: =IFERROR(LN((O20*R20)/(P20*Q20)),"") | W20: =IFERROR(SQRT(1/O20+1/P20+1/Q20+1/R20),"") | X20: =IFERROR(IF(T20<>"",T20,V20),"") | Y20: =IFERROR(IF(U20<>"",U20,W20),"") | Z20: =IFERROR(EXP(X20),"") | AA20: Maybe | AB20: =IF(AA20="Yes",B20,"") | AC20: Doxycycline CDI count reported; comparator unclear | AD20: source table (see PDF) | AE20: UNVERIFIED - needs extraction | AF20: Extract estimate.
A21: E19 | B21: S32 | C21: Tetracyclines (class, pooled) | D21: Tetracycline-class (pooled) | E21: Other antibiotics (pooled) | G21: Adjusted analysis | H21: aOR | I21: Adjusted (multivariable) | J21: 0.94 | K21: 0.43 | L21: 2.04 | M21: 95 | S21: =IF(M21="",1.96,IF(M21=90,1.645,IF(M21=99,2.576,1.96))) | T21: =IFERROR(LN(J21),"") | U21: =IFERROR((LN(L21)-LN(K21))/(2*S21),"") | V21: =IFERROR(LN((O21*R21)/(P21*Q21)),"") | W21: =IFERROR(SQRT(1/O21+1/P21+1/Q21+1/R21),"") | X21: =IFERROR(IF(T21<>"",T21,V21),"") | Y21: =IFERROR(IF(U21<>"",U21,W21),"") | Z21: =IFERROR(EXP(X21),"") | AA21: Yes | AB21: =IF(AA21="Yes",B21,"") | AC21: Crude 1.43 (0.75-2.71) | AD21: source table (see PDF) | AE21: UNVERIFIED - needs extraction | AF21: Tariq anchor.
A22: E20 | B22: S33 | C22: Tetracyclines (class, pooled) | D22: Tetracycline-class (pooled) | E22: Other antibiotics (pooled) | G22: Overall / primary | H22: OR | I22: Unclear | M22: 95 | S22: =IF(M22="",1.96,IF(M22=90,1.645,IF(M22=99,2.576,1.96))) | T22: =IFERROR(LN(J22),"") | U22: =IFERROR((LN(L22)-LN(K22))/(2*S22),"") | V22: =IFERROR(LN((O22*R22)/(P22*Q22)),"") | W22: =IFERROR(SQRT(1/O22+1/P22+1/Q22+1/R22),"") | X22: =IFERROR(IF(T22<>"",T22,V22),"") | Y22: =IFERROR(IF(U22<>"",U22,W22),"") | Z22: =IFERROR(EXP(X22),"") | AA22: Maybe | AB22: =IF(AA22="Yes",B22,"") | AC22: Per-agent CDD incidence/counts (doxy/mino/tetra); no OR vs comparator | AD22: source table (see PDF) | AE22: UNVERIFIED - needs extraction | AF22: Derive 2x2 if possible.
A23: E21 | B23: S34 | C23: Tigecycline | D23: Individual tetracycline agent | E23: Other antibiotics (pooled) | G23: Overall / primary | H23: OR | I23: Adjusted (multivariable) | J23: 0.1 | M23: 95 | S23: =IF(M23="",1.96,IF(M23=90,1.645,IF(M23=99,2.576,1.96))) | T23: =IFERROR(LN(J23),"") | U23: =IFERROR((LN(L23)-LN(K23))/(2*S23),"") | V23: =IFERROR(LN((O23*R23)/(P23*Q23)),"") | W23: =IFERROR(SQRT(1/O23+1/P23+1/Q23+1/R23),"") | X23: =IFERROR(IF(T23<>"",T23,V23),"") | Y23: =IFERROR(IF(U23<>"",U23,W23),"") | Z23: =IFERROR(EXP(X23),"") | AA23: Maybe | AB23: =IF(AA23="Yes",B23,"") | AC23: Tigecycline OR 0.10 (CI not fully captured); tetracycline class not separable | AD23: source table (see PDF) | AE23: UNVERIFIED - needs extraction | AF23: Extract full CI.
A24: E22 | B24: S37 | C24: Doxycycline | D24: Individual tetracycline agent | E24: Other antibiotics (pooled) | G24: Doxycycline-only | H24: aOR | I24: Adjusted (multivariable) | J24: 0.96 | K24: 0.89 | L24: 1.02 | M24: 95 | S24: =IF(M24="",1.96,IF(M24=90,1.645,IF(M24=99,2.576,1.96))) | T24: =IFERROR(LN(J24),"") | U24: =IFERROR((LN(L24)-LN(K24))/(2*S24),"") | V24: =IFERROR(LN((O24*R24)/(P24*Q24)),"") | W24: =IFERROR(SQRT(1/O24+1/P24+1/Q24+1/R24),"") | X24: =IFERROR(IF(T24<>"",T24,V24),"") | Y24: =IFERROR(IF(U24<>"",U24,W24),"") | Z24: =IFERROR(EXP(X24),"") | AA24: Yes | AB24: =IF(AA24="Yes",B24,"") | AD24: source table (see PDF) | AE24: UNVERIFIED - needs extraction | AF24: Per-agent analysis.
A25: E23 | B25: S37 | C25: Minocycline | D25: Individual tetracycline agent | E25: Other antibiotics (pooled) | G25: Other | H25: aOR | I25: Adjusted (multivariable) | J25: 0.79 | K25: 0.67 | L25: 0.93 | M25: 95 | S25: =IF(M25="",1.96,IF(M25=90,1.645,IF(M25=99,2.576,1.96))) | T25: =IFERROR(LN(J25),"") | U25: =IFERROR((LN(L25)-LN(K25))/(2*S25),"") | V25: =IFERROR(LN((O25*R25)/(P25*Q25)),"") | W25: =IFERROR(SQRT(1/O25+1/P25+1/Q25+1/R25),"") | X25: =IFERROR(IF(T25<>"",T25,V25),"") | Y25: =IFERROR(IF(U25<>"",U25,W25),"") | Z25: =IFERROR(EXP(X25),"") | AA25: No | AB25: =IF(AA25="Yes",B25,"") | AC25: Same study (Miller 2023) | AD25: source table (see PDF) | AE25: UNVERIFIED - needs extraction | AF25: Minocycline protective.
A26: E24 | B26: S37 | C26: Tetracycline | D26: Individual tetracycline agent | E26: Other antibiotics (pooled) | G26: Other | H26: aOR | I26: Adjusted (multivariable) | J26: 1.21 | K26: 0.92 | L26: 1.6 | M26: 95 | S26: =IF(M26="",1.96,IF(M26=90,1.645,IF(M26=99,2.576,1.96))) | T26: =IFERROR(LN(J26),"") | U26: =IFERROR((LN(L26)-LN(K26))/(2*S26),"") | V26: =IFERROR(LN((O26*R26)/(P26*Q26)),"") | W26: =IFERROR(SQRT(1/O26+1/P26+1/Q26+1/R26),"") | X26: =IFERROR(IF(T26<>"",T26,V26),"") | Y26: =IFERROR(IF(U26<>"",U26,W26),"") | Z26: =IFERROR(EXP(X26),"") | AA26: No | AB26: =IF(AA26="Yes",B26,"") | AC26: Same study (Miller 2023) | AD26: source table (see PDF) | AE26: UNVERIFIED - needs extraction | AF26: Tetracycline (base) agent.
A27: E25 | B27: S40 | C27: Doxycycline | D27: Individual tetracycline agent | E27: Specific class (see detail) | F27: doxycycline vs azithromycin | G27: Overall / primary | H27: aOR | I27: Adjusted (multivariable) | J27: 0.83 | K27: 0.7 | L27: 0.99 | M27: 95 | S27: =IF(M27="",1.96,IF(M27=90,1.645,IF(M27=99,2.576,1.96))) | T27: =IFERROR(LN(J27),"") | U27: =IFERROR((LN(L27)-LN(K27))/(2*S27),"") | V27: =IFERROR(LN((O27*R27)/(P27*Q27)),"") | W27: =IFERROR(SQRT(1/O27+1/P27+1/Q27+1/R27),"") | X27: =IFERROR(IF(T27<>"",T27,V27),"") | Y27: =IFERROR(IF(U27<>"",U27,W27),"") | Z27: =IFERROR(EXP(X27),"") | AA27: Yes | AB27: =IF(AA27="Yes",B27,"") | AC27: Other models 0.88 (0.73-1.05); severe-CDI 0.55 (0.31-0.91) | AD27: source table (see PDF) | AE27: UNVERIFIED - needs extraction | AF27: Substitution cohort.
A28: E26 | B28: S42 | C28: Tetracyclines (class, pooled) | D28: Tetracycline-class (pooled) | E28: Other antibiotics (pooled) | G28: Crude analysis | H28: OR | I28: Crude / unadjusted | M28: 95 | S28: =IF(M28="",1.96,IF(M28=90,1.645,IF(M28=99,2.576,1.96))) | T28: =IFERROR(LN(J28),"") | U28: =IFERROR((LN(L28)-LN(K28))/(2*S28),"") | V28: =IFERROR(LN((O28*R28)/(P28*Q28)),"") | W28: =IFERROR(SQRT(1/O28+1/P28+1/Q28+1/R28),"") | X28: =IFERROR(IF(T28<>"",T28,V28),"") | Y28: =IFERROR(IF(U28<>"",U28,W28),"") | Z28: =IFERROR(EXP(X28),"") | AA28: Maybe | AB28: =IF(AA28="Yes",B28,"") | AC28: Small crude counts (2 vs 3; p=0.54) | AD28: source table (see PDF) | AE28: UNVERIFIED - needs extraction | AF28: Derive 2x2 with denominators from source.
A29: E27 | B29: S43 | C29: Tetracyclines (class, pooled) | D29: Tetracycline-class (pooled) | E29: No antibiotic / unexposed | G29: Overall / primary | H29: OR | I29: Unclear | M29: 95 | S29: =IF(M29="",1.96,IF(M29=90,1.645,IF(M29=99,2.576,1.96))) | T29: =IFERROR(LN(J29),"") | U29: =IFERROR((LN(L29)-LN(K29))/(2*S29),"") | V29: =IFERROR(LN((O29*R29)/(P29*Q29)),"") | W29: =IFERROR(SQRT(1/O29+1/P29+1/Q29+1/R29),"") | X29: =IFERROR(IF(T29<>"",T29,V29),"") | Y29: =IFERROR(IF(U29<>"",U29,W29),"") | Z29: =IFERROR(EXP(X29),"") | AA29: Maybe | AB29: =IF(AA29="Yes",B29,"") | AC29: Estimate in source table; NOT extractable from PDF text | AD29: source table (see PDF) | AE29: UNVERIFIED - needs extraction | AF29: Manual extraction required (Tariq anchor).
A30: E28 | B30: S44 | C30: Doxycycline | D30: Individual tetracycline agent | E30: Specific class (see detail) | F30: beta-lactam+doxycycline vs other regimens | G30: Overall / primary | H30: aOR | I30: Adjusted (multivariable) | J30: 0.85 | K30: 0.26 | L30: 2.79 | M30: 95 | S30: =IF(M30="",1.96,IF(M30=90,1.645,IF(M30=99,2.576,1.96))) | T30: =IFERROR(LN(J30),"") | U30: =IFERROR((LN(L30)-LN(K30))/(2*S30),"") | V30: =IFERROR(LN((O30*R30)/(P30*Q30)),"") | W30: =IFERROR(SQRT(1/O30+1/P30+1/Q30+1/R30),"") | X30: =IFERROR(IF(T30<>"",T30,V30),"") | Y30: =IFERROR(IF(U30<>"",U30,W30),"") | Z30: =IFERROR(EXP(X30),"") | AA30: Yes | AB30: =IF(AA30="Yes",B30,"") | AC30: Also OR 0.73 (0.44-1.20) | AD30: source table (see PDF) | AE30: UNVERIFIED - needs extraction | AF30: Combination regimen; CDI outcome.
A31: E29 | B31: S45 | C31: Tetracyclines (class, pooled) | D31: Tetracycline-class (pooled) | E31: Reference category (multivariable) | G31: Overall / primary | H31: aOR | I31: Adjusted (multivariable) | J31: 2.97 | K31: 2.44 | L31: 3.63 | M31: 95 | S31: =IF(M31="",1.96,IF(M31=90,1.645,IF(M31=99,2.576,1.96))) | T31: =IFERROR(LN(J31),"") | U31: =IFERROR((LN(L31)-LN(K31))/(2*S31),"") | V31: =IFERROR(LN((O31*R31)/(P31*Q31)),"") | W31: =IFERROR(SQRT(1/O31+1/P31+1/Q31+1/R31),"") | X31: =IFERROR(IF(T31<>"",T31,V31),"") | Y31: =IFERROR(IF(U31<>"",U31,W31),"") | Z31: =IFERROR(EXP(X31),"") | AA31: Yes | AB31: =IF(AA31="Yes",B31,"") | AC31: Counts 262/4917 vs 265/19668 | AD31: source table (see PDF) | AE31: UNVERIFIED - needs extraction | AF31: Nested case-control.
A32: E30 | B32: S49 | C32: Tetracyclines (class, pooled) | D32: Tetracycline-class (pooled) | E32: Other antibiotics (pooled) | G32: Overall / primary | H32: OR | I32: Crude / unadjusted | J32: 6.421 | K32: 2.194 | L32: 14.945 | M32: 95 | S32: =IF(M32="",1.96,IF(M32=90,1.645,IF(M32=99,2.576,1.96))) | T32: =IFERROR(LN(J32),"") | U32: =IFERROR((LN(L32)-LN(K32))/(2*S32),"") | V32: =IFERROR(LN((O32*R32)/(P32*Q32)),"") | W32: =IFERROR(SQRT(1/O32+1/P32+1/Q32+1/R32),"") | X32: =IFERROR(IF(T32<>"",T32,V32),"") | Y32: =IFERROR(IF(U32<>"",U32,W32),"") | Z32: =IFERROR(EXP(X32),"") | AA32: Maybe | AB32: =IF(AA32="Yes",B32,"") | AC32: A reported 'multivariable 0.146 (0.07-0.22)' appears to be a table-parsing artifact - VERIFY | AD32: source table (see PDF) | AE32: UNVERIFIED - needs extraction | AF32: Community-onset.
A33: E31 | B33: S50 | C33: Tetracycline | D33: Individual tetracycline agent | E33: Reference category (multivariable) | F33: penicillin-only reference | G33: Overall / primary | H33: OR | I33: Unclear | J33: 0.6 | K33: 0.14 | L33: 2.52 | M33: 95 | S33: =IF(M33="",1.96,IF(M33=90,1.645,IF(M33=99,2.576,1.96))) | T33: =IFERROR(LN(J33),"") | U33: =IFERROR((LN(L33)-LN(K33))/(2*S33),"") | V33: =IFERROR(LN((O33*R33)/(P33*Q33)),"") | W33: =IFERROR(SQRT(1/O33+1/P33+1/Q33+1/R33),"") | X33: =IFERROR(IF(T33<>"",T33,V33),"") | Y33: =IFERROR(IF(U33<>"",U33,W33),"") | Z33: =IFERROR(EXP(X33),"") | AA33: Yes | AB33: =IF(AA33="Yes",B33,"") | AD33: source table (see PDF) | AE33: UNVERIFIED - needs extraction | AF33: Matched case-control.
A34: E32 | B34: S51 | C34: Tetracyclines (class, pooled) | D34: Tetracycline-class (pooled) | E34: Other antibiotics (pooled) | G34: Overall / primary | H34: OR | I34: Unclear | M34: 95 | S34: =IF(M34="",1.96,IF(M34=90,1.645,IF(M34=99,2.576,1.96))) | T34: =IFERROR(LN(J34),"") | U34: =IFERROR((LN(L34)-LN(K34))/(2*S34),"") | V34: =IFERROR(LN((O34*R34)/(P34*Q34)),"") | W34: =IFERROR(SQRT(1/O34+1/P34+1/Q34+1/R34),"") | X34: =IFERROR(IF(T34<>"",T34,V34),"") | Y34: =IFERROR(IF(U34<>"",U34,W34),"") | Z34: =IFERROR(EXP(X34),"") | AA34: Maybe | AB34: =IF(AA34="Yes",B34,"") | AC34: Tetracycline appears in risk model text | AD34: source table (see PDF) | AE34: UNVERIFIED - needs extraction | AF34: Extract estimate from full text.
A35: E33 | B35: S52 | C35: Doxycycline | D35: Individual tetracycline agent | E35: Other antibiotics (pooled) | G35: Overall / primary | H35: OR | I35: Adjusted (multivariable) | J35: 3.32 | K35: 2.03 | L35: 5.43 | M35: 95 | S35: =IF(M35="",1.96,IF(M35=90,1.645,IF(M35=99,2.576,1.96))) | T35: =IFERROR(LN(J35),"") | U35: =IFERROR((LN(L35)-LN(K35))/(2*S35),"") | V35: =IFERROR(LN((O35*R35)/(P35*Q35)),"") | W35: =IFERROR(SQRT(1/O35+1/P35+1/Q35+1/R35),"") | X35: =IFERROR(IF(T35<>"",T35,V35),"") | Y35: =IFERROR(IF(U35<>"",U35,W35),"") | Z35: =IFERROR(EXP(X35),"") | AA35: No | AB35: =IF(AA35="Yes",B35,"") | AC35: FAERS reporting OR (ROR); pharmacovigilance design EXCLUDED per protocol | AD35: source table (see PDF) | AE35: UNVERIFIED - needs extraction | AF35: Recorded for completeness only.
A36: E34 | B36: S55 | C36: Doxycycline | D36: Individual tetracycline agent | E36: Other antibiotics (pooled) | G36: Overall / primary | H36: OR | I36: Crude / unadjusted | M36: 95 | O36: 7 | P36: 9 | Q36: 93 | S36: =IF(M36="",1.96,IF(M36=90,1.645,IF(M36=99,2.576,1.96))) | T36: =IFERROR(LN(J36),"") | U36: =IFERROR((LN(L36)-LN(K36))/(2*S36),"") | V36: =IFERROR(LN((O36*R36)/(P36*Q36)),"") | W36: =IFERROR(SQRT(1/O36+1/P36+1/Q36+1/R36),"") | X36: =IFERROR(IF(T36<>"",T36,V36),"") | Y36: =IFERROR(IF(U36<>"",U36,W36),"") | Z36: =IFERROR(EXP(X36),"") | AA36: Yes | AB36: =IF(AA36="Yes",B36,"") | AC36: 2x2 partial: cases exposed=7; control denominator (d) needed | AD36: source table (see PDF) | AE36: UNVERIFIED - needs extraction | AF36: p=0.7953.
A37: E35 | B37: S57 | C37: Tetracycline | D37: Individual tetracycline agent | E37: Other antibiotics (pooled) | G37: Crude analysis | H37: OR | I37: Crude / unadjusted | M37: 95 | O37: 2 | P37: 9 | Q37: 16 | R37: 136 | S37: =IF(M37="",1.96,IF(M37=90,1.645,IF(M37=99,2.576,1.96))) | T37: =IFERROR(LN(J37),"") | U37: =IFERROR((LN(L37)-LN(K37))/(2*S37),"") | V37: =IFERROR(LN((O37*R37)/(P37*Q37)),"") | W37: =IFERROR(SQRT(1/O37+1/P37+1/Q37+1/R37),"") | X37: =IFERROR(IF(T37<>"",T37,V37),"") | Y37: =IFERROR(IF(U37<>"",U37,W37),"") | Z37: =IFERROR(EXP(X37),"") | AA37: Yes | AB37: =IF(AA37="Yes",B37,"") | AC37: Crude 2x2 (a=2,b=9,c=16,d=136) | AD37: source table (see PDF) | AE37: UNVERIFIED - needs extraction | AF37: p=0.776; ICU enteral nutrition.
A38: E36 | B38: S58 | C38: Tetracyclines (class, pooled) | D38: Tetracycline-class (pooled) | E38: Other antibiotics (pooled) | G38: HA-CDI | H38: OR | I38: Unclear | J38: 0.393 | K38: 0.305 | L38: 0.506 | M38: 95 | S38: =IF(M38="",1.96,IF(M38=90,1.645,IF(M38=99,2.576,1.96))) | T38: =IFERROR(LN(J38),"") | U38: =IFERROR((LN(L38)-LN(K38))/(2*S38),"") | V38: =IFERROR(LN((O38*R38)/(P38*Q38)),"") | W38: =IFERROR(SQRT(1/O38+1/P38+1/Q38+1/R38),"") | X38: =IFERROR(IF(T38<>"",T38,V38),"") | Y38: =IFERROR(IF(U38<>"",U38,W38),"") | Z38: =IFERROR(EXP(X38),"") | AA38: Yes | AB38: =IF(AA38="Yes",B38,"") | AC38: Protective; confirm adjusted vs crude | AD38: source table (see PDF) | AE38: UNVERIFIED - needs extraction | AF38: Large HO-CDI study.
A39: E37 | B39: S59 | C39: Doxycycline | D39: Individual tetracycline agent | E39: Other antibiotics (pooled) | G39: Adjusted analysis | H39: aOR | I39: Adjusted (multivariable) | J39: 0.5 | K39: 0.3 | L39: 0.8 | M39: 95 | S39: =IF(M39="",1.96,IF(M39=90,1.645,IF(M39=99,2.576,1.96))) | T39: =IFERROR(LN(J39),"") | U39: =IFERROR((LN(L39)-LN(K39))/(2*S39),"") | V39: =IFERROR(LN((O39*R39)/(P39*Q39)),"") | W39: =IFERROR(SQRT(1/O39+1/P39+1/Q39+1/R39),"") | X39: =IFERROR(IF(T39<>"",T39,V39),"") | Y39: =IFERROR(IF(U39<>"",U39,W39),"") | Z39: =IFERROR(EXP(X39),"") | AA39: Yes | AB39: =IF(AA39="Yes",B39,"") | AC39: Also 0.6 (0.3-1.0) | AD39: source table (see PDF) | AE39: UNVERIFIED - needs extraction | AF39: Doxycycline protective.
A40: E38 | B40: S61 | C40: Tetracyclines (class, pooled) | D40: Tetracycline-class (pooled) | E40: Other antibiotics (pooled) | G40: Overall / primary | H40: OR | I40: Unclear | J40: 0.58 | K40: 0.51 | L40: 0.66 | M40: 95 | S40: =IF(M40="",1.96,IF(M40=90,1.645,IF(M40=99,2.576,1.96))) | T40: =IFERROR(LN(J40),"") | U40: =IFERROR((LN(L40)-LN(K40))/(2*S40),"") | V40: =IFERROR(LN((O40*R40)/(P40*Q40)),"") | W40: =IFERROR(SQRT(1/O40+1/P40+1/Q40+1/R40),"") | X40: =IFERROR(IF(T40<>"",T40,V40),"") | Y40: =IFERROR(IF(U40<>"",U40,W40),"") | Z40: =IFERROR(EXP(X40),"") | AA40: Yes | AB40: =IF(AA40="Yes",B40,"") | AC40: Conf abstract | AD40: source table (see PDF) | AE40: UNVERIFIED - needs extraction | AF40: Protective.
...

Sheet Combination_therapy
A1: Combo_ID | B1: Study_ID | C1: Combination_present | D1: Tetracycline_agent | E1: Co_administered_agents | F1: Combo_context | G1: Combo_regimen_description | H1: Combo_vs_comparator | I1: Combo_estimate_type | J1: Combo_point | K1: Combo_CI_lower | L1: Combo_CI_upper | M1: N_combo | N1: N_CDI_in_combo | O1: Notes
A3: C01 | B3: S19 | C3: Yes | D3: Doxycycline | E3: Ceftriaxone | F3: Observed co-exposure | G3: Doxycycline co-administered with ceftriaxone | H3: Ceftriaxone + doxycycline vs ceftriaxone alone | I3: aHR | J3: 0.73 | K3: 0.56 | L3: 0.96 | O3: Doernberg 2012 - combination context central; protective.
A4: C02 | B4: S44 | C4: Yes | D4: Doxycycline | E4: Beta-lactam | F4: Trial regimen arm | G4: Empiric beta-lactam + doxycycline for CAP | H4: Beta-lactam+doxycycline vs beta-lactam+macrolide/other | I4: aOR | J4: 0.85 | K4: 0.26 | L4: 2.79 | O4: Reeves 2024; new CDI ~0.4%; CDI outcome.
A5: C03 | B5: S22 | C5: Yes | D5: Doxycycline | E5: Beta-lactam | F5: Treatment of infection | G5: Beta-lactams + doxycycline for severe CAP | H5: vs azithromycin | O5: Greco Kinney 2023; CDI outcome unclear - verify.
A6: C04 | B6: S45 | C6: Yes | D6: Tetracyclines (class) | E6: Multiple (2/3/4+ agents) | F6: Observed co-exposure | G6: Number of antimicrobial agents analyzed vs CDI | H6: Combinations of 2/3/4+ agents vs single agent | I6: aOR | N6: Saito 2025; extract tetracycline-containing combinations.
A7: C05 | B7: S13 | C7: Yes | D7: Doxycycline | E7: Macrolides | F7: Treatment of infection | G7: Doxycycline commonly given with macrolides in CAP | H7: Combination vs monotherapy | O7: Chalmers 2016; combination frequent - check CDI by regimen.
A8: C06 | B8: S40 | C8: No | D8: Doxycycline | E8: (substitution, not combination) | F8: Observed co-exposure | G8: Doxycycline used IN PLACE OF azithromycin | H8: Doxycycline vs azithromycin | I8: aOR | J8: 0.83 | K8: 0.7 | L8: 0.99 | O8: O'Leary 2023; substitution rather than combination.

Sheet Covariate_matrix
A1: Study_ID | B1: Age | C1: Sex | D1: PPI / acid suppression | E1: H2RA | F1: Other/prior antibiotics | G1: No. of antibiotic classes | H1: Antibiotic duration/DOT | I1: Hospitalization/admission | J1: Length of stay | K1: ICU admission | L1: Comorbidity index (Charlson/APACHE) | M1: Immunosuppression | N1: Malignancy/chemotherapy | O1: IBD | P1: Chronic kidney disease/dialysis | Q1: Diabetes | R1: Prior CDI | S1: Enteral/tube feeding | T1: GI surgery | U1: Calendar period/year | V1: Site/ward (clustering) | W1: Matching_variables | X1: Other_adjustments | Y1: Notes
A2: EX-01 | B2: A = Adjusted | C2: A = Adjusted | D2: A = Adjusted | E2: A = Adjusted | F2: A = Adjusted | G2: A = Adjusted | H2: A = Adjusted | I2: A = Adjusted | J2: A = Adjusted | K2: A = Adjusted | L2: A = Adjusted | M2: A = Adjusted | N2: A = Adjusted | O2: A = Adjusted | P2: A = Adjusted | Q2: A = Adjusted | R2: A = Adjusted | S2: A = Adjusted | T2: A = Adjusted | U2: A = Adjusted | V2: A = Adjusted | W2: example | X2: example | Y2: example
A3: S01
A4: S02
A5: S03
A6: S04
A7: S05
A8: S06
A9: S07
A10: S08
A11: S09
A12: S10
A13: S11
A14: S12
... A67: S65

Sheet RoB_NOS
A1: Study_ID | B1: Design | C1: S1_representativeness | D1: S2_selection_comparison_grp | E1: S3_ascertainment_exposure | F1: S4_outcome_not_present_at_start | G1: C1_comparability_age_mainconf | H1: C2_comparability_antibiotics_other | I1: O1_outcome_assessment | J1: O2_followup_adequate_length | K1: O3_followup_complete | L1: Total_stars (auto) | M1: RoB_level (auto) | N1: Reviewer | O1: Notes
A2: S01 | B2: Case-control | L2: =SUMPRODUCT(IFERROR(VALUE(C2:K2),0)) | M2: =IF(L2="","",IF(L2>=7,"Low",IF(L2>=4,"Moderate","High")))
A3: S02 | B3: Matched case-control | L3: =SUMPRODUCT(IFERROR(VALUE(C3:K3),0)) | M3: =IF(L3="","",IF(L3>=7,"Low",IF(L3>=4,"Moderate","High")))
A4: S03 | B4: Case-control | L4: =SUMPRODUCT(IFERROR(VALUE(C4:K4),0)) | M4: =IF(L4="","",IF(L4>=7,"Low",IF(L4>=4,"Moderate","High")))
A5: S04 | B5: Retrospective cohort | L5: =SUMPRODUCT(IFERROR(VALUE(C5:K5),0)) | M5: =IF(L5="","",IF(L5>=7,"Low",IF(L5>=4,"Moderate","High")))
A6: S05 | B6: ? | L6: =SUMPRODUCT(IFERROR(VALUE(C6:K6),0)) | M6: =IF(L6="","",IF(L6>=7,"Low",IF(L6>=4,"Moderate","High")))
A7: S06 | B7: Case-control | L7: =SUMPRODUCT(IFERROR(VALUE(C7:K7),0)) | M7: =IF(L7="","",IF(L7>=7,"Low",IF(L7>=4,"Moderate","High")))
A8: S07 | B8: Retrospective cohort | L8: =SUMPRODUCT(IFERROR(VALUE(C8:K8),0)) | M8: =IF(L8="","",IF(L8>=7,"Low",IF(L8>=4,"Moderate","High")))
A9: S08 | B9: Retrospective cohort | L9: =SUMPRODUCT(IFERROR(VALUE(C9:K9),0)) | M9: =IF(L9="","",IF(L9>=7,"Low",IF(L9>=4,"Moderate","High")))
A10: S09 | B10: Retrospective cohort | L10: =SUMPRODUCT(IFERROR(VALUE(C10:K10),0)) | M10: =IF(L10="","",IF(L10>=7,"Low",IF(L10>=4,"Moderate","High")))
A11: S10 | B11: Retrospective cohort | L11: =SUMPRODUCT(IFERROR(VALUE(C11:K11),0)) | M11: =IF(L11="","",IF(L11>=7,"Low",IF(L11>=4,"Moderate","High")))
A12: S11 | B12: Retrospective cohort | L12: =SUMPRODUCT(IFERROR(VALUE(C12:K12),0)) | M12: =IF(L12="","",IF(L12>=7,"Low",IF(L12>=4,"Moderate","High")))
A13: S12 | B13: Cross-sectional | L13: =SUMPRODUCT(IFERROR(VALUE(C13:K13),0)) | M13: =IF(L13="","",IF(L13>=7,"Low",IF(L13>=4,"Moderate","High")))
... A66: S65 | B66: Case-control | L66: =SUMPRODUCT(IFERROR(VALUE(C66:K66),0)) | M66: =IF(L66="","",IF(L66>=7,"Low",IF(L66>=4,"Moderate","High")))

Sheet RoB2_RCT
A1: Study_ID | B1: D1_randomization | C1: D2_deviations_intervention | D1: D3_missing_outcome | E1: D4_measurement_outcome | F1: D5_selection_reported_result | G1: Overall_RoB | H1: Reviewer | I1: Notes
A2: (RCTs only — none among current includes; add rows if RCTs are found)

Sheet Analysis_dataset
A1: Study_ID | B1: study_label (auto) | C1: yi = log-OR (auto) | D1: sei (auto) | E1: OR (auto) | F1: OR_CI_low (auto) | G1: OR_CI_high (auto) | H1: design (auto) | I1: care_context (auto) | J1: exposure (auto) | K1: adjusted (auto) | L1: doxycycline_subgroup (auto) | M1: primary_estimate_ID (auto)
A2: S01 | B2: =IFERROR(INDEX(Studies!$B:$B,MATCH(A2,Studies!$A:$A,0))&" "&INDEX(Studies!$C:$C,MATCH(A2,Studies!$A:$A,0)),"") | C2: =IFERROR(INDEX(Estimates!$X:$X,MATCH(A2,Estimates!$AB:$AB,0)),"") | D2: =IFERROR(INDEX(Estimates!$Y:$Y,MATCH(A2,Estimates!$AB:$AB,0)),"") | E2: =IFERROR(EXP(C2),"") | F2: =IFERROR(EXP(C2-1.96*D2),"") | G2: =IFERROR(EXP(C2+1.96*D2),"") | H2: =IFERROR(INDEX(Studies!$K:$K,MATCH(A2,Studies!$A:$A,0)),"") | I2: =IFERROR(INDEX(Studies!$J:$J,MATCH(A2,Studies!$A:$A,0)),"") | J2: =IFERROR(INDEX(Estimates!$C:$C,MATCH(A2,Estimates!$AB:$AB,0)),"") | K2: =IFERROR(INDEX(Estimates!$I:$I,MATCH(A2,Estimates!$AB:$AB,0)),"") | L2: =IFERROR(IF(INDEX(Estimates!$C:$C,MATCH(A2,Estimates!$AB:$AB,0))="Doxycycline","Yes","No"),"") | M2: =IFERROR(INDEX(Estimates!$A:$A,MATCH(A2,Estimates!$AB:$AB,0)),"")
A3: S02 | B3: =IFERROR(INDEX(Studies!$B:$B,MATCH(A3,Studies!$A:$A,0))&" "&INDEX(Studies!$C:$C,MATCH(A3,Studies!$A:$A,0)),"") | C3: =IFERROR(INDEX(Estimates!$X:$X,MATCH(A3,Estimates!$AB:$AB,0)),"") | D3: =IFERROR(INDEX(Estimates!$Y:$Y,MATCH(A3,Estimates!$AB:$AB,0)),"") | E3: =IFERROR(EXP(C3),"") | F3: =IFERROR(EXP(C3-1.96*D3),"") | G3: =IFERROR(EXP(C3+1.96*D3),"") | H3: =IFERROR(INDEX(Studies!$K:$K,MATCH(A3,Studies!$A:$A,0)),"") | I3: =IFERROR(INDEX(Studies!$J:$J,MATCH(A3,Studies!$A:$A,0)),"") | J3: =IFERROR(INDEX(Estimates!$C:$C,MATCH(A3,Estimates!$AB:$AB,0)),"") | K3: =IFERROR(INDEX(Estimates!$I:$I,MATCH(A3,Estimates!$AB:$AB,0)),"") | L3: =IFERROR(IF(INDEX(Estimates!$C:$C,MATCH(A3,Estimates!$AB:$AB,0))="Doxycycline","Yes","No"),"") | M3: =IFERROR(INDEX(Estimates!$A:$A,MATCH(A3,Estimates!$AB:$AB,0)),"")
A4: S03 | B4: =IFERROR(INDEX(Studies!$B:$B,MATCH(A4,Studies!$A:$A,0))&" "&INDEX(Studies!$C:$C,MATCH(A4,Studies!$A:$A,0)),"") | C4: =IFERROR(INDEX(Estimates!$X:$X,MATCH(A4,Estimates!$AB:$AB,0)),"") | D4: =IFERROR(INDEX(Estimates!$Y:$Y,MATCH(A4,Estimates!$AB:$AB,0)),"") | E4: =IFERROR(EXP(C4),"") | F4: =IFERROR(EXP(C4-1.96*D4),"") | G4: =IFERROR(EXP(C4+1.96*D4),"") | H4: =IFERROR(INDEX(Studies!$K:$K,MATCH(A4,Studies!$A:$A,0)),"") | I4: =IFERROR(INDEX(Studies!$J:$J,MATCH(A4,Studies!$A:$A,0)),"") | J4: =IFERROR(INDEX(Estimates!$C:$C,MATCH(A4,Estimates!$AB:$AB,0)),"") | K4: =IFERROR(INDEX(Estimates!$I:$I,MATCH(A4,Estimates!$AB:$AB,0)),"") | L4: =IFERROR(IF(INDEX(Estimates!$C:$C,MATCH(A4,Estimates!$AB:$AB,0))="Doxycycline","Yes","No"),"") | M4: =IFERROR(INDEX(Estimates!$A:$A,MATCH(A4,Estimates!$AB:$AB,0)),"")
A5: S04 | B5: =IFERROR(INDEX(Studies!$B:$B,MATCH(A5,Studies!$A:$A,0))&" "&INDEX(Studies!$C:$C,MATCH(A5,Studies!$A:$A,0)),"") | C5: =IFERROR(INDEX(Estimates!$X:$X,MATCH(A5,Estimates!$AB:$AB,0)),"") | D5: =IFERROR(INDEX(Estimates!$Y:$Y,MATCH(A5,Estimates!$AB:$AB,0)),"") | E5: =IFERROR(EXP(C5),"") | F5: =IFERROR(EXP(C5-1.96*D5),"") | G5: =IFERROR(EXP(C5+1.96*D5),"") | H5: =IFERROR(INDEX(Studies!$K:$K,MATCH(A5,Studies!$A:$A,0)),"") | I5: =IFERROR(INDEX(Studies!$J:$J,MATCH(A5,Studies!$A:$A,0)),"") | J5: =IFERROR(INDEX(Estimates!$C:$C,MATCH(A5,Estimates!$AB:$AB,0)),"") | K5: =IFERROR(INDEX(Estimates!$I:$I,MATCH(A5,Estimates!$AB:$AB,0)),"") | L5: =IFERROR(IF(INDEX(Estimates!$C:$C,MATCH(A5,Estimates!$AB:$AB,0))="Doxycycline","Yes","No"),"") | M5: =IFERROR(INDEX(Estimates!$A:$A,MATCH(A5,Estimates!$AB:$AB,0)),"")
